<mujoco>
  <compiler angle="radian" assetdir="assets"/>
  <option>
    <flag/>
  </option>
  <statistic/>
  <asset>
    <texture type="2d" colorspace="sRGB" name="texture_map" file="texture_map.png"/>
    <texture type="2d" colorspace="linear" name="noise_normal" file="noise_normal.png"/>
    <material name="material_0" rgba="1.0 1.0 1.0 1.0" reflectance="0.5" roughness="1.0" metallic="0.0">
      <layer texture="texture_map" role="rgb"/>
    </material>
    <material name="aluminum_rough" rgba="0.9621279 0.9653596 0.9658199 1.0" reflectance="0.5" roughness="0.54" metallic="1.0" texuniform="true" texrepeat="12.0 12.0">
      <layer texture="noise_normal" role="normal"/>
    </material>
    <material name="black_rubber" rgba="0.2478005 0.2478005 0.2478005 1.0" reflectance="0.5" roughness="0.7318181" metallic="0.0" texuniform="true" texrepeat="16.0 16.0">
      <layer texture="noise_normal" role="normal"/>
    </material>
    <material name="white_metal" rgba="0.8515661 0.8539651 0.8543058 1.0" reflectance="0.5" roughness="0.2" metallic="0.0" texuniform="true" texrepeat="16.0 16.0">
      <layer texture="noise_normal" role="normal"/>
    </material>
    <material name="gray_plastic" rgba="0.865042 0.8670493 0.9063318 1.0" reflectance="0.5" roughness="0.4" metallic="0.0"/>
    <material name="black_metal" rgba="0.0856791 0.0860513 0.0861042 1.0" reflectance="0.5" roughness="0.4" metallic="0.0" texuniform="true" texrepeat="16.0 16.0">
      <layer texture="noise_normal" role="normal"/>
    </material>
    <material name="black_rubber.001" rgba="0.8543058 0.8543058 0.8543058 1.0" reflectance="0.5" roughness="0.7" metallic="0.0" texuniform="true" texrepeat="16.0 16.0">
      <layer texture="noise_normal" role="normal"/>
    </material>
    <material name="template" rgba="0.9063318 0.9063318 0.9063318 1.0" reflectance="0.5" roughness="0.5" metallic="0.0"/>
    <mesh name="ball" file="ball.obj"/>
    <mesh name="link0_0" file="link0_0.obj"/>
    <mesh name="link0_1" file="link0_1.obj"/>
    <mesh name="link0_2" file="link0_2.obj"/>
    <mesh name="link0_3" file="link0_3.obj"/>
    <mesh name="link0_4" file="link0_4.obj"/>
    <mesh name="link0_5" file="link0_5.obj"/>
    <mesh name="link0_7" file="link0_7.obj"/>
    <mesh name="link0_8" file="link0_8.obj"/>
    <mesh name="link0_9" file="link0_9.obj"/>
    <mesh name="link0_10" file="link0_10.obj"/>
    <mesh name="link0_11" file="link0_11.obj"/>
    <mesh name="link1" file="link1.obj"/>
    <mesh name="link2" file="link2.obj"/>
    <mesh name="link3_0" file="link3_0.obj"/>
    <mesh name="link3_1" file="link3_1.obj"/>
    <mesh name="link3_2" file="link3_2.obj"/>
    <mesh name="link3_3" file="link3_3.obj"/>
    <mesh name="link4_0" file="link4_0.obj"/>
    <mesh name="link4_1" file="link4_1.obj"/>
    <mesh name="link4_2" file="link4_2.obj"/>
    <mesh name="link4_3" file="link4_3.obj"/>
    <mesh name="link5_0" file="link5_0.obj"/>
    <mesh name="link5_1" file="link5_1.obj"/>
    <mesh name="link5_2" file="link5_2.obj"/>
    <mesh name="link6_0" file="link6_0.obj"/>
    <mesh name="link6_1" file="link6_1.obj"/>
    <mesh name="link6_2" file="link6_2.obj"/>
    <mesh name="link6_3" file="link6_3.obj"/>
    <mesh name="link6_4" file="link6_4.obj"/>
    <mesh name="link6_5" file="link6_5.obj"/>
    <mesh name="link6_6" file="link6_6.obj"/>
    <mesh name="link6_7" file="link6_7.obj"/>
    <mesh name="link6_8" file="link6_8.obj"/>
    <mesh name="link6_9" file="link6_9.obj"/>
    <mesh name="link6_10" file="link6_10.obj"/>
    <mesh name="link6_11" file="link6_11.obj"/>
    <mesh name="link6_12" file="link6_12.obj"/>
    <mesh name="link6_13" file="link6_13.obj"/>
    <mesh name="link6_14" file="link6_14.obj"/>
    <mesh name="link6_15" file="link6_15.obj"/>
    <mesh name="link6_16" file="link6_16.obj"/>
    <mesh name="base_link" file="base_link.obj"/>
    <mesh name="link_0_0" file="link_0_0.obj"/>
    <mesh name="link_1_0" file="link_1_0.obj"/>
    <mesh name="link_2_0" file="link_2_0.obj"/>
    <mesh name="link_3_0_tip" file="link_3_0_tip.obj"/>
    <mesh name="link_3_0" file="link_3_0.obj"/>
    <mesh name="link_12_0_right" file="link_12_0_right.obj"/>
    <mesh name="link_13_0" file="link_13_0.obj"/>
    <mesh name="link_14_0" file="link_14_0.obj"/>
    <mesh name="link_15_0" file="link_15_0.obj"/>
    <mesh name="link_15_0_tip" file="link_15_0_tip.obj"/>
    <mesh name="link0_c" file="link0_c.stl"/>
    <mesh name="link1_c" file="link1_c.stl"/>
    <mesh name="link2_c" file="link2_c.stl"/>
    <mesh name="link3_c" file="link3_c.stl"/>
    <mesh name="link4_c" file="link4_c.stl"/>
    <mesh name="link5_c0" file="link5_c0.stl"/>
    <mesh name="link5_c1" file="link5_c1.stl"/>
    <mesh name="link5_c2" file="link5_c2.stl"/>
    <mesh name="link6_c" file="link6_c.stl"/>
  </asset>
  <worldbody>
    <body name="link0" pos="0.0 0.0 0.0" quat="1.0 0.0 0.0 0.0">
      <inertial pos="-0.041018 -0.00014 0.049974" quat="1.0 0.0 0.0 0.0" mass="0.629769" fullinertia="0.00315 0.00388 0.004285 8e-07 0.00015 8.2e-06"/>
      <geom name="link0_0" pos="0.0 0.0 0.0" quat="1.0 0.0 0.0 0.0" type="mesh" mesh="link0_0" material="aluminum_rough" group="2" contype="0" conaffinity="0"/>
      <geom name="link0_1" pos="0.0 0.0 0.0" quat="1.0 0.0 0.0 0.0" type="mesh" mesh="link0_1" material="black_rubber" group="2" contype="0" conaffinity="0"/>
      <geom name="link0_10" pos="0.0 0.0 0.0" quat="1.0 0.0 0.0 0.0" type="mesh" mesh="link0_10" material="aluminum_rough" group="2" contype="0" conaffinity="0"/>
      <geom name="link0_11" pos="0.0 0.0 0.0" quat="1.0 0.0 0.0 0.0" type="mesh" mesh="link0_11" material="white_metal" group="2" contype="0" conaffinity="0"/>
      <geom name="link0_2" pos="0.0 0.0 0.0" quat="1.0 0.0 0.0 0.0" type="mesh" mesh="link0_2" material="aluminum_rough" group="2" contype="0" conaffinity="0"/>
      <geom name="link0_3" pos="0.0 0.0 0.0" quat="1.0 0.0 0.0 0.0" type="mesh" mesh="link0_3" material="black_rubber" group="2" contype="0" conaffinity="0"/>
      <geom name="link0_4" pos="0.0 0.0 0.0" quat="1.0 0.0 0.0 0.0" type="mesh" mesh="link0_4" material="aluminum_rough" group="2" contype="0" conaffinity="0"/>
      <geom name="link0_5" pos="0.0 0.0 0.0" quat="1.0 0.0 0.0 0.0" type="mesh" mesh="link0_5" material="aluminum_rough" group="2" contype="0" conaffinity="0"/>
      <geom name="link0_7" pos="0.0 0.0 0.0" quat="1.0 0.0 0.0 0.0" type="mesh" mesh="link0_7" material="white_metal" group="2" contype="0" conaffinity="0"/>
      <geom name="link0_8" pos="0.0 0.0 0.0" quat="1.0 0.0 0.0 0.0" type="mesh" mesh="link0_8" material="white_metal" group="2" contype="0" conaffinity="0"/>
      <geom name="link0_9" pos="0.0 0.0 0.0" quat="1.0 0.0 0.0 0.0" type="mesh" mesh="link0_9" material="black_rubber" group="2" contype="0" conaffinity="0"/>
      <geom name="link0_c" pos="0.0 0.0 0.0" quat="1.0 0.0 0.0 0.0" type="mesh" mesh="link0_c" group="3" contype="0" conaffinity="0"/>
      <body name="link1" pos="0.0 0.0 0.333" quat="0.8571674 0.0 0.0 -0.515038">
        <inertial pos="0.003875 0.002081 -0.04762" quat="1.0 0.0 0.0 0.0" mass="4.9706841" fullinertia="0.70337 0.70661 0.009117 -0.000139 0.006772 0.019169"/>
        <joint name="joint1" pos="0.0 0.0 0.0" axis="0.0 0.0 1.0" type="hinge" range="-2.8973 2.8973" armature="0.1" damping="40.0"/>
        <geom name="link1_001" pos="0.0 0.0 0.0" quat="1.0 0.0 0.0 0.0" type="mesh" mesh="link1" material="white_metal" group="2" contype="0" conaffinity="0"/>
        <geom name="link1_c" pos="0.0 0.0 -0.333" quat="0.8571674 0.0 0.0 0.515038" type="mesh" mesh="link1_c" group="3" contype="0" conaffinity="0"/>
        <body name="link2" pos="0.0 -0.0 1e-07" quat="0.6705783 -0.6705782 -0.2243318 -0.2243318">
          <inertial pos="-0.003141 -0.02872 0.003495" quat="1.0 0.0 -0.0 0.0" mass="0.646926" fullinertia="0.007962 0.02811 0.025995 -0.003925 0.010254 0.000704"/>
          <joint name="joint2" pos="0.0 0.0 0.0" axis="0.0 -0.0 1.0" type="hinge" range="-1.7628 1.7628" armature="0.1" damping="40.0"/>
          <geom name="link2_001" pos="0.0 -0.0 -0.0" quat="1.0 0.0 -0.0 0.0" type="mesh" mesh="link2" material="white_metal" group="2" contype="0" conaffinity="0"/>
          <geom name="link2_c" pos="-0.2003755 0.2659674 -0.0" quat="0.4592585 0.6903374 -0.1530834 0.5376632" type="mesh" mesh="link2_c" group="3" contype="0" conaffinity="0"/>
          <body name="link3" pos="0.0 -0.316 -0.0" quat="0.7070799 0.7070798 0.0061706 -0.0061706">
            <inertial pos="0.027518 0.039252 -0.066502" quat="1.0 0.0 -0.0 0.0" mass="3.2286041" fullinertia="0.037242 0.036155 0.01083 -0.004761 -0.011396 -0.012805"/>
            <joint name="joint3" pos="0.0 0.0 0.0" axis="-0.0 -0.0 1.0" type="hinge" range="-2.8973 2.8973" armature="0.1" damping="40.0"/>
            <geom name="link3_0" pos="0.0 -0.0 -0.0" quat="1.0 0.0 -0.0 0.0" type="mesh" mesh="link3_0" material="white_metal" group="2" contype="0" conaffinity="0"/>
            <geom name="link3_1" pos="0.0 -0.0 -0.0" quat="1.0 0.0 -0.0 0.0" type="mesh" mesh="link3_1" material="black_rubber" group="2" contype="0" conaffinity="0"/>
            <geom name="link3_2" pos="0.0 -0.0 -0.0" quat="1.0 0.0 -0.0 0.0" type="mesh" mesh="link3_2" material="black_rubber" group="2" contype="0" conaffinity="0"/>
            <geom name="link3_3" pos="0.0 -0.0 -0.0" quat="1.0 0.0 -0.0 0.0" type="mesh" mesh="link3_3" material="black_rubber" group="2" contype="0" conaffinity="0"/>
            <geom name="link3_c" pos="-0.200345 -0.0034969 -0.5819675" quat="0.8085936 0.1610181 0.2733546 0.4955067" type="mesh" mesh="link3_c" group="3" contype="0" conaffinity="0"/>
            <body name="link4" pos="0.0825 0.0 -2e-07" quat="0.1936759 0.1936759 0.6800659 -0.6800659">
              <inertial pos="-0.05317 0.104419 0.027454" quat="1.0 -0.0 0.0 0.0" mass="3.5878949" fullinertia="0.025853 0.019552 0.028323 0.007796 -0.001332 0.008641"/>
              <joint name="joint4" pos="0.0 0.0 0.0" axis="0.0 -0.0 1.0" type="hinge" range="-3.0718 -0.0698" armature="0.1" damping="40.0"/>
              <geom name="link4_0" pos="0.0 -0.0 0.0" quat="1.0 0.0 0.0 0.0" type="mesh" mesh="link4_0" material="black_rubber" group="2" contype="0" conaffinity="0"/>
              <geom name="link4_1" pos="0.0 -0.0 0.0" quat="1.0 0.0 0.0 0.0" type="mesh" mesh="link4_1" material="white_metal" group="2" contype="0" conaffinity="0"/>
              <geom name="link4_2" pos="0.0 -0.0 0.0" quat="1.0 0.0 0.0 0.0" type="mesh" mesh="link4_2" material="black_rubber" group="2" contype="0" conaffinity="0"/>
              <geom name="link4_3" pos="0.0 -0.0 0.0" quat="1.0 0.0 0.0 0.0" type="mesh" mesh="link4_3" material="black_rubber" group="2" contype="0" conaffinity="0"/>
              <geom name="link4_c" pos="0.5470155 0.3456311 0.003497" quat="0.0367123 -0.648296 -0.2914842 0.7024254" type="mesh" mesh="link4_c" group="3" contype="0" conaffinity="0"/>
              <body name="link5" pos="-0.0825001 0.3839999 -1e-07" quat="0.4858025 -0.4858017 0.5138062 0.5138053">
                <inertial pos="-0.011953 0.041065 -0.038437" quat="1.0 0.0 -0.0 0.0" mass="1.2259459" fullinertia="0.035549 0.029474 0.008627 -0.002117 -0.004037 0.000229"/>
                <joint name="joint5" pos="0.0 0.0 0.0" axis="-0.0 0.0 1.0" type="hinge" range="-2.8973 2.8973" armature="0.1" damping="2.0"/>
                <geom name="link5_0" pos="-0.0 -0.0 -0.0" quat="1.0 0.0 -0.0 0.0" type="mesh" mesh="link5_0" material="black_rubber" group="2" contype="0" conaffinity="0"/>
                <geom name="link5_1" pos="-0.0 -0.0 -0.0" quat="1.0 0.0 -0.0 0.0" type="mesh" mesh="link5_1" material="aluminum_rough" group="2" contype="0" conaffinity="0"/>
                <geom name="link5_2" pos="-0.0 -0.0 -0.0" quat="1.0 0.0 -0.0 0.0" type="mesh" mesh="link5_2" material="white_metal" group="2" contype="0" conaffinity="0"/>
                <geom name="link5_c0" pos="-0.0387352 -0.6283326 -0.0383679" quat="0.5439219 -0.8077855 -0.1686082 -0.152325" type="mesh" mesh="link5_c0" group="3" contype="0" conaffinity="0"/>
                <geom name="link5_c1" pos="-0.0387352 -0.6283326 -0.0383679" quat="0.5439219 -0.8077855 -0.1686082 -0.152325" type="mesh" mesh="link5_c1" group="3" contype="0" conaffinity="0"/>
                <geom name="link5_c2" pos="-0.0387352 -0.6283326 -0.0383679" quat="0.5439219 -0.8077855 -0.1686082 -0.152325" type="mesh" mesh="link5_c2" group="3" contype="0" conaffinity="0"/>
                <body name="link6" pos="-1e-07 -1e-07 -1e-07" quat="0.0297841 0.0297841 -0.7064793 0.7064792">
                  <inertial pos="0.060149 -0.014117 -0.010517" quat="1.0 0.0 -0.0 0.0" mass="1.666555" fullinertia="0.001964 0.004354 0.005433 0.000109 -0.001158 0.000341"/>
                  <joint name="joint6" pos="0.0 0.0 0.0" axis="-0.0 0.0 1.0" type="hinge" range="-0.0175 3.7525001" armature="0.1" damping="2.0"/>
                  <geom name="link6_0" pos="0.0 -0.0 0.0" quat="1.0 0.0 0.0 1e-07" type="mesh" mesh="link6_0" material="aluminum_rough" group="2" contype="0" conaffinity="0"/>
                  <geom name="link6_1" pos="0.0 -0.0 0.0" quat="1.0 0.0 0.0 1e-07" type="mesh" mesh="link6_1" material="black_rubber" group="2" contype="0" conaffinity="0"/>
                  <geom name="link6_10" pos="0.0 -0.0 0.0" quat="1.0 0.0 0.0 1e-07" type="mesh" mesh="link6_10" material="black_rubber" group="2" contype="0" conaffinity="0"/>
                  <geom name="link6_11" pos="0.0 -0.0 0.0" quat="1.0 0.0 0.0 1e-07" type="mesh" mesh="link6_11" material="gray_plastic" group="2" contype="0" conaffinity="0"/>
                  <geom name="link6_12" pos="0.0 -0.0 0.0" quat="1.0 0.0 0.0 1e-07" type="mesh" mesh="link6_12" material="gray_plastic" group="2" contype="0" conaffinity="0"/>
                  <geom name="link6_13" pos="0.0 -0.0 0.0" quat="1.0 0.0 0.0 1e-07" type="mesh" mesh="link6_13" material="gray_plastic" group="2" contype="0" conaffinity="0"/>
                  <geom name="link6_14" pos="0.0 -0.0 0.0" quat="1.0 0.0 0.0 1e-07" type="mesh" mesh="link6_14" material="black_rubber" group="2" contype="0" conaffinity="0"/>
                  <geom name="link6_15" pos="0.0 -0.0 0.0" quat="1.0 0.0 0.0 1e-07" type="mesh" mesh="link6_15" material="black_rubber" group="2" contype="0" conaffinity="0"/>
                  <geom name="link6_16" pos="0.0 -0.0 0.0" quat="1.0 0.0 0.0 1e-07" type="mesh" mesh="link6_16" material="white_metal" group="2" contype="0" conaffinity="0"/>
                  <geom name="link6_2" pos="0.0 -0.0 0.0" quat="1.0 0.0 0.0 1e-07" type="mesh" mesh="link6_2" material="black_rubber" group="2" contype="0" conaffinity="0"/>
                  <geom name="link6_3" pos="0.0 -0.0 0.0" quat="1.0 0.0 0.0 1e-07" type="mesh" mesh="link6_3" material="black_rubber" group="2" contype="0" conaffinity="0"/>
                  <geom name="link6_4" pos="0.0 -0.0 0.0" quat="1.0 0.0 0.0 1e-07" type="mesh" mesh="link6_4" material="black_rubber" group="2" contype="0" conaffinity="0"/>
                  <geom name="link6_5" pos="0.0 -0.0 0.0" quat="1.0 0.0 0.0 1e-07" type="mesh" mesh="link6_5" material="black_rubber" group="2" contype="0" conaffinity="0"/>
                  <geom name="link6_6" pos="0.0 -0.0 0.0" quat="1.0 0.0 0.0 1e-07" type="mesh" mesh="link6_6" material="black_rubber" group="2" contype="0" conaffinity="0"/>
                  <geom name="link6_7" pos="0.0 -0.0 0.0" quat="1.0 0.0 0.0 1e-07" type="mesh" mesh="link6_7" material="gray_plastic" group="2" contype="0" conaffinity="0"/>
                  <geom name="link6_8" pos="0.0 -0.0 0.0" quat="1.0 0.0 0.0 1e-07" type="mesh" mesh="link6_8" material="gray_plastic" group="2" contype="0" conaffinity="0"/>
                  <geom name="link6_9" pos="0.0 -0.0 0.0" quat="1.0 0.0 0.0 1e-07" type="mesh" mesh="link6_9" material="white_metal" group="2" contype="0" conaffinity="0"/>
                  <geom name="link6_c" pos="0.0353684 0.0414918 0.6283327" quat="0.0036449 -0.266992 0.9453945 0.1868993" type="mesh" mesh="link6_c" group="3" contype="0" conaffinity="0"/>
                  <body name="link7" pos="0.0880001 -0.0 1e-07" quat="0.7071068 0.7071068 0.0 0.0">
                    <joint name="joint7" pos="0.0 0.0 0.0" axis="0.0 0.0 1.0" type="hinge" range="-2.8973 2.8973" armature="0.1" damping="2.0"/>
                    <geom name="ball" pos="-0.1172306 0.0058809 0.1658868" quat="0.5151688 -0.7436379 0.2291444 -0.3593004" type="mesh" mesh="ball" material="material_0" group="2"/>
                    <body name="palm" pos="0.0092894 -3e-07 0.1467656" quat="1.0 1e-06 1e-07 0.0" gravcomp="1.0">
                      <geom name="base_link" pos="-0.0 0.0 -1e-07" quat="1.0 0.0 -0.0 -0.0" type="mesh" mesh="base_link" material="black_metal" group="2" contype="0" conaffinity="0" density="800.0"/>
                      <geom name="GEO_Box" pos="-0.0093 0.0 -0.0475" quat="0.1862147 0.1913688 -0.800652 0.536338" type="box" size="0.0204 0.0565 0.0475" material="template" group="3" density="800.0"/>
                      <body name="ff_base" pos="-0.0 0.0434999 -0.001542" quat="0.9987252 -0.0436053 -0.0011092 0.0254042">
                        <joint name="ffj0" pos="0.0 0.0 0.0" axis="0.0 0.0 1.0" type="hinge" range="-0.47 0.47" armature="0.01" damping="0.1"/>
                        <geom name="GEO_Box_001" pos="0.0 0.0 0.0082" quat="0.1921459 0.1794998 -0.8276735 0.4957987" type="box" size="0.0098 0.01375 0.0082" material="template" group="3" density="800.0"/>
                        <geom name="link_0_0" pos="0.0 -1e-07 0.0" quat="1.0 -0.0 0.0 -0.0" type="mesh" mesh="link_0_0" material="black_metal" group="2" contype="0" conaffinity="0" density="800.0"/>
                        <body name="ff_proximal" pos="-0.0 -2e-07 0.0164001" quat="0.9275917 0.0 -0.3735956 0.0">
                          <joint name="ffj1" pos="0.0 0.0 0.0" axis="0.0 1.0 1e-07" type="hinge" range="-0.196 1.61" armature="0.01" damping="0.1"/>
                          <geom name="GEO_Box_002" pos="0.0 0.0 0.027" quat="0.4874482 0.3517308 -0.6959583 0.3928385" type="box" size="0.0098 0.01375 0.027" material="template" group="3" density="800.0"/>
                          <geom name="link_1_0" pos="0.0 -0.0 0.0" quat="1.0 -0.0 -0.0 0.0" type="mesh" mesh="link_1_0" material="black_metal" group="2" contype="0" conaffinity="0" density="800.0"/>
                          <body name="ff_medial" pos="1e-07 1e-07 0.054" quat="0.9275985 0.0 -0.3735787 -0.0">
                            <joint name="ffj2" pos="0.0 0.0 0.0" axis="0.0 1.0 1e-07" type="hinge" range="-0.174 1.709" armature="0.01" damping="0.1"/>
                            <geom name="GEO_Box_003" pos="0.0 0.0 0.0192" quat="0.7121513 0.4730208 -0.4634697 0.2329972" type="box" size="0.0098 0.01375 0.0192" material="template" group="3" density="800.0"/>
                            <geom name="link_2_0" pos="-1e-07 -1e-07 0.0" quat="1.0 0.0 -0.0 0.0" type="mesh" mesh="link_2_0" material="black_metal" group="2" contype="0" conaffinity="0" density="800.0"/>
                            <body name="ff_distal" pos="1e-07 -2e-07 0.0384" quat="0.9275892 0.0 -0.3736019 -0.0">
                              <joint name="ffj3" pos="0.0 0.0 0.0" axis="0.0 1.0 1e-07" type="hinge" range="-0.227 1.618" armature="0.01" damping="0.1"/>
                              <geom name="GEO_Box_004" pos="0.0 0.0 0.008" quat="0.833737 0.5258172 -0.1638483 0.0394043" type="box" size="0.0098 0.01375 0.008" material="template" group="3" density="800.0"/>
                              <geom name="link_3_0" pos="0.0 1e-07 0.0" quat="1.0 0.0 -0.0 0.0" type="mesh" mesh="link_3_0" material="black_metal" group="2" contype="0" conaffinity="0" density="800.0"/>
                              <body name="ff_tip" pos="-1e-07 -1e-07 -1e-07" quat="1.0 0.0 0.0 -0.0">
                                <geom name="ff_tip_col" pos="0.0 0.0 0.019" quat="0.833737 0.5258172 -0.1638483 0.0394043" type="capsule" size="0.012 0.01" material="template" group="3" condim="6" friction="2.0 0.05 0.01" density="800.0"/>
                                <geom name="link_3_0_tip" pos="0.0 0.0 0.0267" quat="1.0 -0.0 0.0 0.0" type="mesh" mesh="link_3_0_tip" material="black_rubber.001" group="2" contype="0" conaffinity="0" density="800.0"/>
                              </body>
                            </body>
                          </body>
                        </body>
                      </body>
                      <body name="mf_base" pos="-0.0 1e-07 0.0007" quat="0.9995176 -0.0 0.0 -0.031059">
                        <joint name="mfj0" pos="0.0 0.0 0.0" axis="1e-07 0.0 1.0" type="hinge" range="-0.47 0.47" armature="0.01" damping="0.1"/>
                        <geom name="GEO_Box_005" pos="0.0 0.0 0.0082" quat="0.1694668 0.2161439 -0.7943221 0.5418628" type="box" size="0.0098 0.01375 0.0082" material="template" group="3" density="800.0"/>
                        <geom name="link_001" pos="0.0 0.0 0.0" quat="1.0 -0.0 0.0 0.0" type="mesh" mesh="link_0_0" material="black_metal" group="2" contype="0" conaffinity="0" density="800.0"/>
                        <body name="mf_proximal" pos="1e-07 0.0 0.0164" quat="0.9427835 -0.0 -0.3334057 0.0">
                          <joint name="mfj1" pos="0.0 0.0 0.0" axis="-0.0 1.0 1e-07" type="hinge" range="-0.196 1.61" armature="0.01" damping="0.1"/>
                          <geom name="GEO_Box_006" pos="0.0 0.0 0.027" quat="0.424602 0.3844371 -0.6923725 0.4387958" type="box" size="0.0098 0.01375 0.027" material="template" group="3" density="800.0"/>
                          <geom name="link_002" pos="0.0 0.0 0.0" quat="1.0 0.0 0.0 0.0" type="mesh" mesh="link_1_0" material="black_metal" group="2" contype="0" conaffinity="0" density="800.0"/>
                          <body name="mf_medial" pos="0.0 -4e-07 0.054" quat="0.9507728 -0.0 -0.3098888 0.0">
                            <joint name="mfj2" pos="0.0 0.0 0.0" axis="0.0 1.0 1e-07" type="hinge" range="-0.174 1.709" armature="0.01" damping="0.1"/>
                            <geom name="GEO_Box_007" pos="0.0 0.0 0.0192" quat="0.6182587 0.5014905 -0.5267095 0.2980624" type="box" size="0.0098 0.01375 0.0192" material="template" group="3" density="800.0"/>
                            <geom name="link_003" pos="0.0 0.0 0.0" quat="1.0 -0.0 -0.0 0.0" type="mesh" mesh="link_2_0" material="black_metal" group="2" contype="0" conaffinity="0" density="800.0"/>
                            <body name="mf_distal" pos="0.0 0.0 0.0384001" quat="0.9508801 -0.0 -0.3095595 0.0">
                              <joint name="mfj3" pos="0.0 0.0 0.0" axis="0.0 1.0 1e-07" type="hinge" range="-0.227 1.618" armature="0.01" damping="0.1"/>
                              <geom name="GEO_Box_008" pos="0.0 0.0 0.008" quat="0.7509376 0.5691248 -0.3094499 0.1281806" type="box" size="0.0098 0.01375 0.008" material="template" group="3" density="800.0"/>
                              <geom name="link_004" pos="0.0 0.0 0.0" quat="1.0 -0.0 -0.0 -0.0" type="mesh" mesh="link_3_0" material="black_metal" group="2" contype="0" conaffinity="0" density="800.0"/>
                              <body name="mf_tip" pos="0.0 -2e-07 0.0" quat="1.0 0.0 -1e-07 1e-07">
                                <geom name="link_3_0_001" pos="1e-07 0.0 0.0267" quat="1.0 -0.0 0.0 0.0" type="mesh" mesh="link_3_0_tip" material="black_rubber.001" group="2" contype="0" conaffinity="0" density="800.0"/>
                                <geom name="mf_tip_col" pos="0.0 0.0 0.019" quat="0.7509377 0.5691248 -0.3094499 0.1281805" type="capsule" size="0.012 0.01" material="template" group="3" condim="6" friction="2.0 0.05 0.01" density="800.0"/>
                              </body>
                            </body>
                          </body>
                        </body>
                      </body>
                      <body name="rf_base" pos="-0.0 -0.0434999 -0.0015422" quat="0.9960707 0.0434894 -0.0033652 -0.0770747">
                        <joint name="rfj0" pos="0.0 0.0 0.0" axis="-0.0 0.0 1.0" type="hinge" range="-0.47 0.47" armature="0.01" damping="0.1"/>
                        <geom name="GEO_Box_009" pos="0.0 0.0 0.0082" quat="0.1551618 0.2460333 -0.7588047 0.5827589" type="box" size="0.0098 0.01375 0.0082" material="template" group="3" density="800.0"/>
                        <geom name="link_005" pos="0.0 0.0 0.0" quat="1.0 0.0 -0.0 -0.0" type="mesh" mesh="link_0_0" material="black_metal" group="2" contype="0" conaffinity="0" density="800.0"/>
                        <body name="rf_proximal" pos="-0.0 -1e-07 0.0164001" quat="0.9204001 0.0 -0.3909777 -0.0">
                          <joint name="rfj1" pos="0.0 0.0 0.0" axis="-0.0 1.0 1e-07" type="hinge" range="-0.196 1.61" armature="0.01" damping="0.1"/>
                          <geom name="GEO_Box_010" pos="0.0 0.0 0.027" quat="0.4394868 0.4542949 -0.6377391 0.4401778" type="box" size="0.0098 0.01375 0.027" material="template" group="3" density="800.0"/>
                          <geom name="link_006" pos="0.0 0.0 0.0" quat="1.0 0.0 0.0 0.0" type="mesh" mesh="link_1_0" material="black_metal" group="2" contype="0" conaffinity="0" density="800.0"/>
                          <body name="rf_medial" pos="2e-07 1e-07 0.054" quat="0.916375 0.0 -0.400321 0.0">
                            <joint name="rfj2" pos="0.0 0.0 0.0" axis="0.0 1.0 1e-07" type="hinge" range="-0.174 1.709" armature="0.01" damping="0.1"/>
                            <geom name="GEO_Box_011" pos="0.0 0.0 0.0192" quat="0.6580347 0.5925169 -0.4084726 0.2215039" type="box" size="0.0098 0.01375 0.0192" material="template" group="3" density="800.0"/>
                            <geom name="link_007" pos="0.0 0.0 0.0" quat="1.0 0.0 -0.0 0.0" type="mesh" mesh="link_2_0" material="black_metal" group="2" contype="0" conaffinity="0" density="800.0"/>
                            <body name="rf_distal" pos="0.0 1e-07 0.0383999" quat="0.9841714 0.0 -0.1772193 -0.0">
                              <joint name="rfj3" pos="0.0 0.0 0.0" axis="0.0 1.0 1e-07" type="hinge" range="-0.227 1.618" armature="0.01" damping="0.1"/>
                              <geom name="GEO_Box_012" pos="0.0 0.0 0.008" quat="0.7200084 0.6223928 -0.2853904 0.1129927" type="box" size="0.0098 0.01375 0.008" material="template" group="3" density="800.0"/>
                              <geom name="link_008" pos="0.0 0.0 0.0" quat="1.0 0.0 -0.0 -0.0" type="mesh" mesh="link_3_0" material="black_metal" group="2" contype="0" conaffinity="0" density="800.0"/>
                              <body name="rf_tip" pos="-2e-07 4e-07 -0.0" quat="1.0 -0.0 -1e-07 -0.0">
                                <geom name="link_009" pos="0.0 0.0 0.0267" quat="1.0 0.0 -0.0 0.0" type="mesh" mesh="link_3_0_tip" material="black_rubber.001" group="2" contype="0" conaffinity="0" density="800.0"/>
                                <geom name="rf_tip_col" pos="0.0 0.0 0.019" quat="0.7200084 0.6223928 -0.2853902 0.1129926" type="capsule" size="0.012 0.01" material="template" group="3" condim="6" friction="2.0 0.05 0.01" density="800.0"/>
                              </body>
                            </body>
                          </body>
                        </body>
                      </body>
                      <body name="th_base" pos="-0.0182 0.0193331 -0.0459872" quat="0.6740978 0.0489692 -0.7356498 0.044872">
                        <joint name="thj0" pos="0.0 0.0 0.0" axis="-1.0 -1e-07 -1e-07" type="hinge" range="0.263 1.396" armature="0.01" damping="0.1"/>
                        <geom name="GEO_Box_013" pos="-0.0179 0.009 0.0145" quat="0.7479641 0.4785126 -0.3850523 0.2516153" type="box" size="0.0179 0.017 0.02275" material="template" group="3" density="800.0"/>
                        <geom name="link_12_0_right" pos="-1e-07 0.0 0.0" quat="1.0 0.0 0.0 -0.0" type="mesh" mesh="link_12_0_right" material="black_metal" group="2" contype="0" conaffinity="0" density="800.0"/>
                        <body name="th_proximal" pos="-0.0270001 0.0050001 0.0398999" quat="1.0 0.0 0.0 -0.0">
                          <joint name="thj1" pos="0.0 0.0 0.0" axis="0.0 0.0 1.0" type="hinge" range="-0.105 1.163" armature="0.01" damping="0.1"/>
                          <geom name="GEO_Box_014" pos="0.0 0.0 0.00885" quat="0.7479641 0.4785125 -0.3850523 0.2516153" type="box" size="0.0098 0.01375 0.00885" material="template" group="3" density="800.0"/>
                          <geom name="link_13_0" pos="0.0 1e-07 0.0" quat="1.0 -0.0 0.0 -0.0" type="mesh" mesh="link_13_0" material="black_metal" group="2" contype="0" conaffinity="0" density="800.0"/>
                          <body name="th_medial" pos="-2e-07 2e-07 0.0177" quat="0.9693884 0.0 0.2455325 -0.0">
                            <joint name="thj2" pos="0.0 0.0 0.0" axis="0.0 1.0 1e-07" type="hinge" range="-0.189 1.6440001" armature="0.01" damping="0.1"/>
                            <geom name="GEO_Box_015" pos="0.0 0.0 0.0257" quat="0.6305248 0.4020848 -0.5569148 0.3614034" type="box" size="0.0098 0.01375 0.0257" material="template" group="3" density="800.0"/>
                            <geom name="link_14_0" pos="0.0 1e-07 0.0" quat="1.0 -0.0 -0.0 -0.0" type="mesh" mesh="link_14_0" material="black_metal" group="2" contype="0" conaffinity="0" density="800.0"/>
                            <body name="th_distal" pos="-0.0 0.0 0.0514" quat="0.9433336 -0.0 0.3318459 -0.0">
                              <joint name="thj3" pos="0.0 0.0 0.0" axis="-1e-07 1.0 1e-07" type="hinge" range="-0.162 1.719" armature="0.01" damping="0.1"/>
                              <geom name="GEO_Box_016" pos="0.0 0.0 0.0157" quat="0.4099857 0.25937 -0.7345933 0.4743541" type="box" size="0.0098 0.01375 0.0157" material="template" group="3" density="800.0"/>
                              <geom name="link_15_0" pos="1e-07 1e-07 0.0" quat="1.0 0.0 0.0 0.0" type="mesh" mesh="link_15_0" material="black_metal" group="2" contype="0" conaffinity="0" density="800.0"/>
                              <body name="th_tip" pos="2e-07 3e-07 -0.0" quat="1.0 0.0 1e-07 1e-07">
                                <geom name="link_15_0_tip" pos="-0.0 -0.0 0.0423" quat="1.0 -0.0 0.0 -0.0" type="mesh" mesh="link_15_0_tip" material="black_rubber.001" group="2" contype="0" conaffinity="0" density="800.0"/>
                                <geom name="th_tip_col" pos="0.0 0.0 0.035" quat="0.4099857 0.2593699 -0.7345933 0.4743542" type="capsule" size="0.012 0.008" material="template" group="3" condim="6" friction="2.0 0.05 0.01" density="800.0"/>
                              </body>
                            </body>
                          </body>
                        </body>
                      </body>
                    </body>
                  </body>
                </body>
              </body>
            </body>
          </body>
        </body>
      </body>
    </body>
  </worldbody>
  <contact>
    <exclude body1="palm" body2="ff_base"/>
    <exclude body1="palm" body2="mf_base"/>
    <exclude body1="palm" body2="rf_base"/>
    <exclude body1="palm" body2="th_base"/>
    <exclude body1="palm" body2="th_proximal"/>
  </contact>
  <equality/>
  <actuator>
    <position name="actuator1" joint="joint1" ctrlrange="-2.8973 2.8973" forcerange="-100.0 100.0" kp="1000.0" kv="20.0"/>
    <position name="actuator2" joint="joint2" ctrlrange="-1.7628 1.7628" forcerange="-100.0 100.0" kp="1000.0" kv="20.0"/>
    <position name="actuator3" joint="joint3" ctrlrange="-2.8973 2.8973" forcerange="-100.0 100.0" kp="750.0" kv="4.0"/>
    <position name="actuator4" joint="joint4" ctrlrange="-3.0718 -0.0698" forcerange="-100.0 100.0" kp="750.0" kv="4.0"/>
    <position name="actuator5" joint="joint5" ctrlrange="-2.8973 2.8973" forcerange="-12.0 12.0" kp="300.0" kv="2.0"/>
    <position name="actuator6" joint="joint6" ctrlrange="-0.0175 3.7525001" forcerange="-12.0 12.0" kp="300.0" kv="2.0"/>
    <position name="actuator7" joint="joint7" forcerange="-12.0 12.0" kp="300.0" kv="2.0"/>
    <position name="rfa0" joint="rfj0" ctrlrange="-0.47 0.47"/>
    <position name="mfa2" joint="mfj2" ctrlrange="-0.174 1.709"/>
    <position name="ffa2" joint="ffj2" ctrlrange="-0.174 1.709"/>
    <position name="rfa3" joint="rfj3" ctrlrange="-0.227 1.618"/>
    <position name="tha0" joint="thj0" ctrlrange="0.263 1.396"/>
    <position name="rfa2" joint="rfj2" ctrlrange="-0.174 1.709"/>
    <position name="rfa1" joint="rfj1" ctrlrange="-0.196 1.61"/>
    <position name="ffa3" joint="ffj3" ctrlrange="-0.227 1.618"/>
    <position name="mfa3" joint="mfj3" ctrlrange="-0.227 1.618"/>
    <position name="ffa0" joint="ffj0" ctrlrange="-0.47 0.47"/>
    <position name="tha1" joint="thj1" ctrlrange="-0.105 1.163"/>
    <position name="tha2" joint="thj2" ctrlrange="-0.189 1.6440001"/>
    <position name="tha3" joint="thj3" ctrlrange="-0.162 1.719"/>
    <position name="mfa1" joint="mfj1" ctrlrange="-0.196 1.61"/>
    <position name="ffa1" joint="ffj1" ctrlrange="-0.196 1.61"/>
    <position name="mfa0" joint="mfj0" ctrlrange="-0.47 0.47"/>
  </actuator>
</mujoco>
